package org.djunits.unit.util;

import static org.junit.Assert.assertEquals;
import static org.junit.Assert.assertNull;
import static org.junit.Assert.assertTrue;
import static org.junit.Assert.fail;

import org.junit.Test;

/**
 * UnitExceptionTest.java.
 * <p>
 * Copyright (c) 2019-2022 Delft University of Technology, PO Box 5, 2600 AA, Delft, the Netherlands. All rights reserved. <br>
 * BSD-style license. See <a href="https://djunits.org/docs/license.html">DJUNITS License</a>
 * </p>
 * @author <a href="https://www.tudelft.nl/averbraeck" target="_blank">Alexander Verbraeck</a>
 */
public class UnitExceptionTest
{
    /** test the UnitException. */
    @Test
    public void testException()
    {
        try
        {
            throw new UnitException();
        }
        catch (UnitException e)
        {
            assertNull(e.getMessage());
        }
        catch (Exception exception)
        {
            fail("Right exception not thrown");
        }

        try
        {
            throw new UnitException("abc");
        }
        catch (UnitException e)
        {
            assertEquals("abc", e.getMessage());
        }
        catch (Exception exception)
        {
            fail("Right exception not thrown");
        }

        try
        {
            throw new UnitException(new IllegalArgumentException());
        }
        catch (UnitException e)
        {
            assertTrue(e.getMessage().contains("IllegalArgumentException"));
            assertTrue(e.getCause() instanceof IllegalArgumentException);
        }
        catch (Exception exception)
        {
            fail("Right exception not thrown");
        }

        try
        {
            throw new UnitException("abc", new IllegalArgumentException("def"));
        }
        catch (UnitException e)
        {
            assertEquals("abc", e.getMessage());
            assertTrue(e.getCause() instanceof IllegalArgumentException);
            assertEquals("def", e.getCause().getMessage());
        }
        catch (Exception exception)
        {
            fail("Right exception not thrown");
        }
    }
}
